Workbook
Name _Hlk10462746: 'BBDD Equipos 60598'!$F$106
Name _Hlk99628035: 'BBDD Equipos 60598'!$AX$12

Sheet RESUMEN PROYECTO LUM
F2: v2.1 | H2: COMENTARIOS Y NOTAS GENERALES DEL PROYECTO
B3: CÓDIGO SERVICIO: | D3: NNNNNAAAA
B4: TÉCNICO RESPONS:
C5: Técnico 1:
C6: Técnico 2:
C8: Nº Muestras | D8: 1 | E8: (Máx. 8)
C9: Ta | E9: ºC
C10: Clase
B11: =IF(OR(D4=0,D8=0,D9=0),"FALTA POR MARACAR INFORMACIÓN DE PROYECTO","") -> FALTA POR MARACAR INFORMACIÓN DE PROYECTO
H12: Ver tempertura y humedad de ensayo en registro del servidor
B14: NORMAS DE APLICACIÓN (ver edición en TRF) | H14: GRADO IP (OBJETIVO) | O14: GRADOS IK (OBJETIVO)
D21: =#REF! -> #REF!
D25: =IF('Datos ensayos LUM.'!O6=FALSE,"FALTA POR MARCAR NORMAS A APLICAR","") -> #REF! | H25: =IF(AND('Datos ensayos LUM.'!I10=TRUE,'RESUMEN PROYECTO LUM'!L25=0),"INDICAR PROFUNDIDAD","") | K25: Profund. (m):
H26: =IF(AND('Datos ensayos LUM.'!K9=TRUE,'RESUMEN PROYECTO LUM'!L26=0),"INDICAR TEMPERATURA","") | K26: Temp. (ºC):
I27: =IF('Datos ensayos LUM.'!O12=FALSE,"FALTA POR MARCAR PRIMERA CIFRA IP","") -> FALTA POR MARCAR PRIMERA CIFRA IP
I28: =IF('Datos ensayos LUM.'!O10=FALSE,"FALTA POR MARCAR SEGUNDA CIFRA IP","") -> FALTA POR MARCAR SEGUNDA CIFRA IP | P28: =IF('Datos ensayos LUM.'!O15=FALSE,"FALTA POR MARCAR INFORMACIÓN IK","") -> FALTA POR MARCAR INFORMACIÓN IK
B29: EDICIONES DE NORMAS APLICADAS:
B30: ='Datos ensayos LUM.'!BN10 -> IEC 60598-1:2024; | I30: Comentarios: | P30: Comentarios:
B32: ='Datos ensayos LUM.'!BN12 -> EN IEC 60598-1:2024 + A11:2024;
B34: ='Datos ensayos LUM.'!BN14 -> #REF!
B37: IDENTIFICACIÓN DE MUESTRAS
D38: Iniciar numeración en: | F38: 1 | G38: COMENTARIOS Y OBSERVACIONES DE LAS MUESTRAS
D39: =IF('Datos ensayos LUM.'!I7,"(Escribir el número en columna sombreada)","")
A40: =F38 -> 1 | B40: =IF($D$8>=1,CONCATENATE("MUESTRA ",A40)," ") -> MUESTRA 1 | C40: =IF($D$8>=1,CONCATENATE("EBP_SAFE",$D$3)," ") -> EBP_SAFENNNNNAAAA | E40: =IF($D$8>=1,IF('Datos ensayos LUM.'!$I$7=TRUE,'RESUMEN PROYECTO LUM'!F40,'RESUMEN PROYECTO LUM'!A40)," ") -> 1
A41: =A40+1 -> 2 | B41: =IF($D$8>=2,CONCATENATE("MUESTRA ",A41)," ") | C41: =IF($D$8>=2,CONCATENATE("EBP_SAFE",$D$3)," ") | E41: =IF($D$8>=2,IF('Datos ensayos LUM.'!$I$7=TRUE,'RESUMEN PROYECTO LUM'!F41,'RESUMEN PROYECTO LUM'!A41)," ")
A42: =A41+1 -> 3 | B42: =IF($D$8>=3,CONCATENATE("MUESTRA ",A42)," ") | C42: =IF($D$8>=3,CONCATENATE("EBP_SAFE",$D$3)," ") | E42: =IF($D$8>=3,IF('Datos ensayos LUM.'!$I$7=TRUE,'RESUMEN PROYECTO LUM'!F42,'RESUMEN PROYECTO LUM'!A42)," ")
A43: =A42+1 -> 4 | B43: =IF($D$8>=4,CONCATENATE("MUESTRA ",A43)," ") | C43: =IF($D$8>=4,CONCATENATE("EBP_SAFE",$D$3)," ") | E43: =IF($D$8>=4,IF('Datos ensayos LUM.'!$I$7=TRUE,'RESUMEN PROYECTO LUM'!F43,'RESUMEN PROYECTO LUM'!A43)," ")
A44: =A43+1 -> 5 | B44: =IF($D$8>=5,CONCATENATE("MUESTRA ",A44)," ") | C44: =IF($D$8>=5,CONCATENATE("EBP_SAFE",$D$3)," ") | E44: =IF($D$8>=5,IF('Datos ensayos LUM.'!$I$7=TRUE,'RESUMEN PROYECTO LUM'!F44,'RESUMEN PROYECTO LUM'!A44)," ")
A45: =A44+1 -> 6 | B45: =IF($D$8>=6,CONCATENATE("MUESTRA ",A45)," ") | C45: =IF($D$8>=6,CONCATENATE("EBP_SAFE",$D$3)," ") | E45: =IF($D$8>=6,IF('Datos ensayos LUM.'!$I$7=TRUE,'RESUMEN PROYECTO LUM'!F45,'RESUMEN PROYECTO LUM'!A45)," ")
A46: =A45+1 -> 7 | B46: =IF($D$8>=7,CONCATENATE("MUESTRA ",A46)," ") | C46: =IF($D$8>=7,CONCATENATE("EBP_SAFE",$D$3)," ") | E46: =IF($D$8>=7,IF('Datos ensayos LUM.'!$I$7=TRUE,'RESUMEN PROYECTO LUM'!F46,'RESUMEN PROYECTO LUM'!A46)," ")
A47: =A46+1 -> 8 | B47: =IF($D$8>=8,CONCATENATE("MUESTRA ",A47)," ") | C47: =IF($D$8>=8,CONCATENATE("EBP_SAFE",$D$3)," ") | E47: =IF($D$8>=8,IF('Datos ensayos LUM.'!$I$7=TRUE,'RESUMEN PROYECTO LUM'!F47,'RESUMEN PROYECTO LUM'!A47)," ")
B49: HISTORICO DEL PROYECTO:

Sheet Toma de notas 60598
A1: PROYECTO: | C1: {='RESUMEN PROYECTO LUM'!D3:E3} -> NNNNNAAAA | D1: 0 | G1: =IF('Datos ensayos LUM.'!$D$7>=1,'RESUMEN PROYECTO LUM'!B40,"") -> MUESTRA 1 | H1: =IF('Datos ensayos LUM.'!$D$7>=2,'RESUMEN PROYECTO LUM'!B41,"") | I1: =IF('Datos ensayos LUM.'!$D$7>=3,'RESUMEN PROYECTO LUM'!B42,"") | J1: =IF('Datos ensayos LUM.'!$D$7>=4,'RESUMEN PROYECTO LUM'!B43,"") | K1: =IF('Datos ensayos LUM.'!$D$7>=5,'RESUMEN PROYECTO LUM'!B44,"") | L1: =IF('Datos ensayos LUM.'!$D$7>=6,'RESUMEN PROYECTO LUM'!B45,"") | M1: =IF('Datos ensayos LUM.'!$D$7>=7,'RESUMEN PROYECTO LUM'!B46,"") | N1: =IF('Datos ensayos LUM.'!$D$7>=8,'RESUMEN PROYECTO LUM'!B47,"")
B3: RATINGS Y OTROS DATOS GENERALES
D4: T(ºC) | E4: H(%) | F4: FECHA
D7: Verificación y medida ratings de la luminaria (Tensión 1) | F7: Tensión (V)
F8: Corriente (A)
F9: Potencia (W)
F10: Fact. Pot (PF)
D12: Verificación y medida ratings de la luminaria (Tensión 2, si procede) | F12: Tensión (V)
F13: Corriente (A)
F14: Potencia (W)
F15: Fact. Pot (PF)
C17: =IF('Datos ensayos LUM.'!D25=1,"IMPRESCINDIBLE RELLENAR ESTOS DATOS","") | D17: Tamaño de las muestras | F17: Alto (cm)
F18: Ancho (cm)
F19: Profundo (cm)
B24: VERIFICACIÓN PARTES ACTIVAS
D25: T(ºC) | E25: H(%) | F25: FECHA
F26: 15
B27: =IF('Datos ensayos LUM.'!M21=1,"SELECCIONA UNA OPCIÓN","") -> SELECCIONA UNA OPCIÓN | C27: ¿Es SELV?
B31: =IF('Datos ensayos LUM.'!M22=1,"SELECCIONA UNA OPCIÓN","") -> SELECCIONA UNA OPCIÓN | C31: ¿Es parte activa? | D31: Medidas para determinar si es parte activa | F31: Vac | G31: 15
F32: Vdc | G32: 15
F33: Uout (driver) | G33: 15
C35: Comentarios:
B43: SECCIÓN 6 - MARCADO
D44: T(ºC) | E44: H(%) | F44: FECHA
D46: Los datos pueden tomarse directamente sobre el TRF
C49: Comentarios:
B55: SECCIÓN 7 - CONSTRUCCIÓN
B57: 7.4 | C57: Portalámparas
D58: T(ºC) | E58: H(%) | F58: FECHA
B60: 7.4.4 | C60: Portalámparas para lámparas fluorescentes:
C64: Comentarios:
C70: Soportes montaje casquillo rosca Edisón o bayoneta
C75: Comentarios:
B82: 7.6 y 7.7.2 | C82: Bornes y conexiones
D83: T(ºC) | E83: H(%) | F83: FECHA
C85: Ensayo de vena 8mm
B86: =IF('Datos ensayos LUM.'!D85<>FALSE,"ELEGIR UNA OPCIÓN","") -> ELEGIR UNA OPCIÓN | D86: Los datos pueden tomarse directamente sobre el TRF
C89: Comentarios:
C94: Dimensiones del bloque de conexión
B95: =IF(OR('Datos ensayos LUM.'!L75,'Datos ensayos LUM.'!L76,'Datos ensayos LUM.'!L77)<>TRUE,"ELEGIR UNA OPCIÓN","") -> ELEGIR UNA OPCIÓN
...

Sheet BBDD Equipos 60598
A1: EQUIPOS UTILIZADOS PARA ENSAYOS
A2: CÓDIGO PROYECTO: | D2: {='RESUMEN PROYECTO LUM'!D3:E3} -> NNNNNAAAA | E2: 0
B4: SECCIÓN 6 | F4: SECCIÓN 7 | J4: SECCIÓN 13 | N4: SECCIÓN 9 | R4: SECCIÓN 8 | V4: SECCIÓN 10 | Z4: SECCIÓN 14 | AD4: SECCIÓN 11 | AH4: SECCIÓN 12 | AL4: SECCIÓN 153 | AP4: SECCIÓN 16 | AT4: IDENT. PARTE ACTIVA | AX4: ENSAYOS ADICIONALES DE PARTES -2 | BB4: IK
C5: 6.5. Verificación del marcado | G5: 7.4.4. Colocación fácil y correcta de los portalámparas | K5: 13.2. Líneas de fuga y distancias en el aire | O5: 9. Continuidad circuito tierra | S5: 8.2 Conexiones a la red y otros cableados externos | W5: 8. Protección contra choque eléctrico | AA5: 14. Endurancia / Calentamientos / Humedad | AE5: 11. Ensayos de IP y humedad | AI5: 12.2.1. Resistencia de aislamiento | AM5: 15.2. Resistencia al calor | AQ5: EQ-SAFE-428 | AR5: Multímetro Fluke | AU5: Anexo A (Partes activas) | AX5: 60598-2-3 | BC5: EN 62262:2002 + A1:2021 / IEC TR 62696:2011
C6: RC-SAFE-015 | D6: Hexano | G6: EQ-SAFE-213 | H6: Dinamómetro | K6: EQ-SAFE-207 | L6: Micrómetro | N6: =IF('Datos ensayos LUM.'!T28=TRUE,"X","") -> X | O6: EQ-SAFE-442 | P6: Medidor de continuidad de tierra (ELABO) | S6: EQ-SAFE-213 | T6: Dinamómetro | W6: EQ-SAFE-122 | X6: Dedo de prueba normalizado | Z6: =IF('Datos ensayos LUM.'!AJ23=TRUE,"X","") | AA6: EQ-SAFE-301 | AB6: Cámara panelable | AD6: =IF('Datos ensayos LUM.'!AR47=TRUE,"X","") | AE6: EQ-SAFE-174 + EQ-SAFE-210 | AF6: Arco de lluvia + Caudalímetro | AH6: =IF('Datos ensayos LUM.'!BE26=TRUE,"X","") | AI6: EQ-SAFE-403 | AJ6: Medidor resistencia de aislamiento (GW INSTEK) | AM6: EQ-SAFE-305 | AN6: Estufa | AQ6: EQ-SAFE-430 | AR6: Multímetro/Pinza UNI-T | AT6: X | AU6: EQ-SAFE-417 | AV6: Multimetro UNI-T | AY6: 3.6.3.1. Ensayo de carga estática | BC6: EQ-SAFE-212 | BD6: Flexómetro
C7: EQ-SAFE-311; EQ-SAFE-312; EQ-SAFE-313 | D7: Termohigrómetros | G7: EQ-SAFE-216 | H7: Llave dinamométrica | K7: EQ-SAFE-206 | L7: Pie de rey | N7: =IF('Datos ensayos LUM.'!T29=TRUE,"X","") | O7: EQ-SAFE-403 | P7: Medidor de continuidad de tierra (GW INSTEK.) | S7: EQ-SAFE-235 EQ-SAFE-236 | T7: Llave dinamométrica hasta 4 N.m Llave dinamométrica entre 4 N.m y 40N.m | W7: EQ-SAFE-107 | X7: Sonda 50mm diámetro | Z7: =IF('Datos ensayos LUM.'!AJ24=TRUE,"X","") | AA7: EQ-SAFE-302 | AB7: Cámara panelable | AD7: =IF('Datos ensayos LUM.'!AR48=TRUE,"X","") | AE7: EQ-SAFE-105 | AF7: Boquillas | AH7: =IF('Datos ensayos LUM.'!BE28=TRUE,"X","") | AI7: EQ-SAFE-403 | AJ7: Medidor resistencia de aislamiento (GW INSTEK) | AM7: EQ-SAFE-328 | AN7: Registrador | AQ7: EQ-SAFE-425 | AR7: Multímetro laboratorio TEKTRONIX | AT7: X | AU7: EQ-SAFE-428 | AV7: Multímetro Fluke | AY7: EQ-SAFE-201 | AZ7: Balanza | BC7: EQ-SAFE-206 | BD7: Pie de rey
C8: EQ-SAFE-407 | D8: Cronómetro digital | G8: EQ-SAFE-206 | H8: Pie de rey | K8: EQ-SAFE-212 | L8: Flexómetro | O8: EQ-SAFE-311; EQ-SAFE-312; EQ-SAFE-313 | P8: Termohigrómetros | S8: EQ-SAFE-311; EQ-SAFE-312; EQ-SAFE-313 | T8: Termohigrómetros | V8: =IF('Datos ensayos LUM.'!AB49=TRUE,"X","") | W8: EQ-SAFE-437 | X8: Multimetro UNI-T | Z8: =IF('Datos ensayos LUM.'!AJ25=TRUE,"X","") | AA8: EQ-SAFE-328 | AB8: Estufa endurancias DYCOMETAL | AD8: =IF('Datos ensayos LUM.'!AR46=TRUE,"X","") | AE8: EQ-SAFE-111 | AF8: Cabeza de regadera (si R necesario > 120cm) | AI8: EQ-SAFE-311; EQ-SAFE-312; EQ-SAFE-313 | AJ8: Termohigrómetros | AM8: EQ-SAFE-323 | AN8: Registrador 20 canales Graphtec | AQ8: EQ-SAFE-206 | AR8: Pie de rey | AU8: EQ-SAFE-430 | AV8: Multímetro/Pinza UNI-T | AY8: EQ-SAFE-311; EQ-SAFE-312; EQ-SAFE-313 | AZ8: Termohigrómetros | BC8: EQ-SAFE-311; EQ-SAFE-312; EQ-SAFE-313 | BD8: Termohigrómetro
C9: Otros: | G9: EQ-SAFE-207 | H9: Micrómetro digital | K9: EQ-SAFE-605 | L9: Lámina cinta 0,1-2,00mm | O9: Otros: | S9: EQ-SAFE-606 | T9: Zumbador Fig. 34 IEC 60598-1:2020 | V9: =IF('Datos ensayos LUM.'!AB50=TRUE,"X","") | W9: EQ-SAFE-428 | X9: Multímetro Fluke | Z9: =IF('Datos ensayos LUM.'!AJ26=TRUE,"X","") | AA9: EQ-SAFE-303 | AB9: Cámara climática (3) | AD9: =IF('Datos ensayos LUM.'!AR49=TRUE,"X","") | AE9: EQ-SAFE-608 | AF9: Depósitos de inmersión | AI9: Otros: | AM9: EQ-SAFE-324 | AN9: Registrador 20 canales Graphtec (Maletín) | AQ9: EQ-SAFE-207 | AR9: Micrómetro | AT9: =IF('Datos ensayos LUM.'!BG24=TRUE,"X","") | AU9: EQ-SAFE-441 | AV9: Corrientes de fuga (contacto). AINUO | AY9: Otros: | BB9: =IF('Toma de notas 60598'!B1070,"X","") | BC9: EQ-SAFE-102 | BD9: Péndulo de golpeo (con su correspondiente pesa)
G10: EQ-SAFE-311; EQ-SAFE-312; EQ-SAFE-313 | H10: Termohigrómetros | K10: EQ-SAFE-167 | L10: Juego de galgas | S10: Otros: | V10: =IF('Datos ensayos LUM.'!AB51=TRUE,"X","") | W10: EQ-SAFE-430 | X10: Multímetro/Pinza UNI-T | Z10: =IF('Datos ensayos LUM.'!AJ32=TRUE,"X","") | AA10: EQ-SAFE-327 | AB10: Medidor temperatura 40 canales | AD10: =IF('Datos ensayos LUM.'!AR45=TRUE,"X","") | AE10: EQ-SAFE-615 | AF10: Caja de goteo | AL10: X | AM10: EQ-SAFE-318 | AN10: Comprobador termopares 2 canales | AQ10: EQ-SAFE-167 | AR10: Juego de galgas | AT10: =IF('Datos ensayos LUM.'!BG25=TRUE,"X","") | AU10: EQ-SAFE-404 | AV10: Corrientes de fuga lum. GW INSTEK GLC-1000 | BB10: =IF('Toma de notas 60598'!B1071,"X","") | BC10: EQ-SAFE-103 | BD10: Equipo de IK para caida vertical
G11: EQ-SAFE-407 | H11: Cronómetro digital | K11: EQ-SAFE-409; EQ-SAFE-121 | L11: Osciloscopio | W11: EQ-SAFE-409; EQ-SAFE-121 | X11: Osciloscopio FLUKE | Z11: =IF('Datos ensayos LUM.'!AJ33=TRUE,"X","") | AA11: EQ-SAFE-328 | AB11: Medidor temperatura 32 canales | AD11: =IF('Datos ensayos LUM.'!AR50=TRUE,"X","") | AE11: EQ-SAFE-232 | AF11: Boquillas de Tobera + Pulverizador + Bomba de presión | AM11: EQ-SAFE-104 | AN11: Presión con bola | AQ11: EQ-SAFE-214 | AR11: Atornillador dinamométrico 60cNm | AU11: EQ-SAFE-409; EQ-SAFE-121 | AV11: Osciloscopio | BB11: =IF('Toma de notas 60598'!B1069,"X","") | BC11: EQ-SAFE-101 | BD11: Martillo Resorte
G12: Otros: | K12: EQ-SAFE-440 | L12: Vatímetro GW-INSTEK | W12: EQ-SAFE-106 | X12: Dedo de prueba articulado | Z12: =IF('Datos ensayos LUM.'!AJ34=TRUE,"X","") | AA12: EQ-SAFE-323 | AB12: Registrador 20+20 canales Graphtec | AE12: EQ-SAFE-211 | AF12: Caudalímetro | AI12: 12.2.2. Rigidez dieléctrica | AM12: EQ-SAFE-604 | AN12: Microscopio | AQ12: EQ-SAFE-215 | AR12: Atornillador dinamométrico 260cNm | AU12: EQ-SAFE-608 | AV12: Resistencia para partes activas | AY12: 3.6.5. Rotura cubiertas cristal | BC12: Otros:
K13: EQ-SAFE-417 | L13: Multímetro digital | W13: EQ-SAFE-213 | X13: Dinamómetro | Z13: =IF('Datos ensayos LUM.'!AJ35=TRUE,"X","") | AA13: EQ-SAFE-324 | AB13: Registrador 20+20 canales Graphtec | AE13: EQ-SAFE-106 | AF13: Dedo de prueba articulado | AH13: =IF('Datos ensayos LUM.'!BF26=TRUE,"X","") | AI13: EQ-SAFE-402 | AJ13: Rigidez dieléctrica (GW INSTEK GPT 15002) | AM13: EQ-SAFE-121 | AN13: Regla graduada | AQ13: EQ-SAFE-213 | AR13: Dinamómetro 500N | AU13: EQ-SAFE-311; EQ-SAFE-312; EQ-SAFE-313 | AV13: Termohigrómetros | AY13: EQ-SAFE-173 | AZ13: Punzón
B14: EQUIPOS A UTILIZAR PARA CADA UNO DE LOS ENSAYOS (LEYENDA) | K14: EQ-SAFE-311; EQ-SAFE-312; EQ-SAFE-313 | L14: Termohigrómetros | W14: EQ-SAFE-221 | X14: Dinamómetro | AA14: EQ-SAFE-001 | AB14: Estabilizador de tensión | AE14: EQ-SAFE-206 | AF14: Pie de rey | AH14: =IF('Datos ensayos LUM.'!BF24=TRUE,"X","") -> X | AI14: EQ-SAFE-403 | AJ14: Rigidez dieléctrica (GW INSTEK GPT 15004) | AM14: EQ-SAFE-311; EQ-SAFE-312; EQ-SAFE-313 | AN14: Termohigrómetros | AQ14: EQ-SAFE-221 | AR14: Dinamómetro 10N | AU14: Otros: | AY14: EQ-SAFE-311; EQ-SAFE-312; EQ-SAFE-313 | AZ14: Termohigrómetros
B15: … | C15: En caso de utilizar equipos adicionales debe indicarse en el apartado "otros" | G15: 7.6. Bloques de conexión | K15: Otros: | W15: EQ-SAFE-311; EQ-SAFE-312; EQ-SAFE-313 | X15: Termohigrómetros | AA15: EQ-SAFE-011 | AB15: Medidor de resistencias de bobinado | AE15: EQ-SAFE-107 EQ-SAFE-112 | AF15: Varilla 50mm diámetro Esfera 50mm diámetro | AH15: =IF('Datos ensayos LUM.'!BF28=TRUE,"X","") | AI15: EQ-SAFE-403 | AJ15: Rigidez dieléctrica (GW INSTEK) | AM15: EQ-SAFE-407 | AN15: Cronómetro | AQ15: EQ-SAFE-407 | AR15: Cronómetro | AY15: Otros:
B16: X | C16: Las casillas coloreadas (excepto amarillo) indican equipos alternativos. Para estas casillas deben marcarse con una "X" sólo los equipos que procedan | G16: EQ-SAFE-206 | H16: Pie de rey | W16: Otros: | AA16: Otros: | AE16: EQ-SAFE-108 | AF16: Varilla 2,5mm diámetro | AI16: EQ-SAFE-311; EQ-SAFE-312; EQ-SAFE-313 | AJ16: Termohigrómetros | AM16: Otros: | AQ16: EQ-SAFE-311; EQ-SAFE-312; EQ-SAFE-313 | AR16: Termohigrómetros
B17: NO | C17: Se asume que los equipo de cailla en blanco se han utilizado ya que son equipos por defecto. Si agún equipo de las casillas blancas no se ha utilizado debe eliminarse, tacharse o indicar "NO" en la casilla de selección | G17: EQ-SAFE-207 | H17: Micrómetro digital | AE17: EQ-SAFE-110 | AF17: Esfera 12,5mm diámetro | AI17: Otros: | AQ17: Otros: | AY17: 3.6.5.2. Cristal gran resistencia 3.6.8. Puerta de acceso
G18: EQ-SAFE-311; EQ-SAFE-312; EQ-SAFE-313 | H18: Termohigrómetros | AE18: EQ-SAFE-109 | AF18: Varilla 1 mm diámetro | AY18: EN 62262:2002 + A1:2021 / IEC TR 62696:2011
C19: Las celdas marcadas en amarillo corresponden con "novedades" o warnings y se resaltan para llamar la atención de los técnicos de ensayo. | G19: Otros: | AE19: EQ-SAFE-309; EQ-SAFE-310 | AF19: Termohigrómetros | AM19: 15.3.1 Resistencia a la llama y a la inflamación | AY19: EQ-SAFE-212 | AZ19: Flexómetro
AE20: EQ-SAFE-212 | AF20: Flexómetro | AI20: 12.3. Corrientes de fuga | AM20: EQ-SAFE-307 | AN20: Llama de aguja | AY20: EQ-SAFE-206 | AZ20: Pie de rey
AE21: EQ-SAFE-330 | AF21: Cámara climática | AH21: =IF('Datos ensayos LUM.'!BG27=TRUE,"X","") -> X | AI21: EQ-SAFE-441 | AJ21: Corrientes de fuga AINUO | AM21: EQ-SAFE-308 | AN21: Mechero Bunsen | AY21: EQ-SAFE-311; EQ-SAFE-312; EQ-SAFE-313 | AZ21: Termohigrómetro
G22: 7.7.2. Bornes y conexiones a la red de alimentación | AD22: =IF('Datos ensayos LUM.'!BF26=TRUE,"X","") | AE22: EQ-SAFE-403 | AF22: Rigidez dieléctrica | AH22: =IF('Datos ensayos LUM.'!BG25=TRUE,"X","") | AI22: EQ-SAFE-404 | AJ22: Corrientes de fuga GW INSTEK - GLC-1000 | AM22: EQ-SAFE-407 | AN22: Cronómetro | AP22: SECCIÓN 17 | AY22: EQ-SAFE-102 | AZ22: Péndulo de golpeo (IK08)
G23: EQ-SAFE-206 | H23: Pie de rey | AD23: =IF('Datos ensayos LUM.'!BF27=TRUE,"X","") | AE23: EQ-SAFE-402 | AF23: Rigidez dieléctrica | AI23: EQ-SAFE-311; EQ-SAFE-312; EQ-SAFE-313 | AJ23: Termohigrómetros | AM23: EQ-SAFE-311; EQ-SAFE-312; EQ-SAFE-313 | AN23: Termohigrómetros | AQ23: EQ-SAFE-428 | AR23: Multímetro Fluke | AY23: Otros:
G24: EQ-SAFE-207 | H24: Micrómetro digital | AD24: =IF('Datos ensayos LUM.'!BF28=TRUE,"X","") | AE24: EQ-SAFE-403 | AF24: Rigidez dieléctrica (GW INSTEK) | AI24: Otros: | AM24: RC-SAFE-013 | AN24: Gas propano | AQ24: EQ-SAFE-430 | AR24: Multímetro/Pinza UNI-T
G25: EQ-SAFE-311; EQ-SAFE-312; EQ-SAFE-313 | H25: Termohigrómetros | AD25: =IF('Datos ensayos LUM.'!BE26=TRUE,"X","") | AE25: EQ-SAFE-403 | AF25: Medidor resistencia de aislamiento | AM25: Otros: | AQ25: EQ-SAFE-417 | AR25: Multímetro laboratorio
G26: Otros: | AD26: =IF('Datos ensayos LUM.'!BE28=TRUE,"X","") | AE26: EQ-SAFE-403 | AF26: Medidor resistencia de aislamiento | AQ26: EQ-SAFE-206 | AR26: Pie de rey
AE27: EQ-SAFE-407 | AF27: Cronómetro digital | AQ27: EQ-SAFE-207 | AR27: Micrómetro | AX27: 60598-2-4
AD28: =IF('Datos ensayos LUM.'!AV70=TRUE,"X","") | AE28: EQ-SAFE-326 | AF28: Cámara de polvo | AM28: 15.3.2 Hilo inandescente | AQ28: EQ-SAFE-167 | AR28: Juego de galgas | AY28: EQ-SAFE-217 | AZ28: Inclinómetro
G29: 7.9. Revestimientos y manguitos aislantes | AE29: Otros: | AM29: EQ-SAFE-306 | AN29: Equipo de hilo incandescente | AQ29: EQ-SAFE-330 | AR29: Cámara climática | AY29: EQ-SAFE-311; EQ-SAFE-312; EQ-SAFE-313 | AZ29: Termohigrómetros
F30: =IF('Datos ensayos LUM.'!D108=TRUE,"X","") -> X | G30: EQ-SAFE-305 | H30: Estufa / horno | AM30: EQ-SAFE-407 | AN30: Cronómetro | AQ30: EQ-SAFE-213 | AR30: Dinamómetro 500N | AY30: Otros:
F31: =IF('Datos ensayos LUM.'!D109=TRUE,"X","") | G31: EQ-SAFE-304 | H31: Estufa / Horno AUTOSTRONG | AM31: EQ-SAFE-311; EQ-SAFE-312; EQ-SAFE-313 | AN31: Termohigrómetros | AQ31: EQ-SAFE-221 | AR31: Dinamómetro 10N
G32: EQ-SAFE-301 | H32: Recinto de temperaturas | AM32: Otros: | AQ32: EQ-SAFE-407 | AR32: Cronómetro
G33: EQ-SAFE-330 | H33: Cámara climática | AQ33: EQ-SAFE-311; EQ-SAFE-312; EQ-SAFE-313 | AR33: Termohigrómetros
G34: EQ-SAFE-206 | H34: Pie de rey | AQ34: Otros: | AX34: 60598-2-5
F35: =IF('Datos ensayos LUM.'!BF26=TRUE,"X","") | G35: EQ-SAFE-403 | H35: Rigidez dieléctrica | AY35: 5.6.5. Ensayo de carga estática
F36: =IF('Datos ensayos LUM.'!BF27=TRUE,"X","") | G36: EQ-SAFE-402 | H36: Rigidez dieléctrica + Resist aisl + Tierra | AM36: 15.4 Frormación de caminos conductores | AY36: EQ-SAFE-201 | AZ36: Balanza
F37: =IF('Datos ensayos LUM.'!BF28=TRUE,"X","") | G37: EQ-SAFE-402 | H37: Rigidez dieléctrica + Resist aisl + Tierra | AM37: EQ-SAFE-444 | AN37: Banco de pruebas eléctricas | AY37: EQ-SAFE-311; EQ-SAFE-312; EQ-SAFE-313 | AZ37: Termohigrómetros
F38: =IF('Datos ensayos LUM.'!BE26=TRUE,"X","") | G38: EQ-SAFE-402 | H38: Rigidez dieléctrica + Resist aisl + Tierra | AM38: EQ-SAFE-407 | AN38: Cronómetro | AY38: Otros:
F39: =IF('Datos ensayos LUM.'!BE28=TRUE,"X","") | G39: EQ-SAFE-402 | H39: Rigidez dieléctrica + Resist aisl + Tierra | AM39: EQ-SAFE-167 | AN39: Juego de Galgas
G40: EQ-SAFE-311; EQ-SAFE-312; EQ-SAFE-313 | H40: Termohigrómetros | AM40: EQ-SAFE-206 | AN40: Pie de rey
G41: EQ-SAFE-407 | H41: Cronómetro digital | AM41: EQ-SAFE-405 | AN41: Conductímetro | AY41: 5.6.8.1. Rotura cubiertas cristal
...

Sheet Datos ensayos LUM.
BE2: Ediciones de normas empleadas
B3: Generales de proyecto | BF3: TEXTO IEC | BG3: TEXTO EN | BH3: FACTOR | BI3: IMPR IEC | BJ3: IMPR EN | BO3: TEXTO IEC | BP3: TEXTO EN | BQ3: FACTOR | BR3: IMPR IEC | BS3: IMPR EN
Q4: SIN CUBIERTA | R4: CON CUBIERTA | X4: Estado del proyecto (secciones importantes) [EN FASE DE IMPLEMENTACIÓN] | AX4: UNIDADES | AY4: (%) | BE4: 60598-1 | BF4: IEC 60598-1:2024; | BG4: EN IEC 60598-1:2024 + A11:2024; | BH4: TRUE | BI4: =IF(BH4=TRUE,BF4," ") -> IEC 60598-1:2024; | BJ4: =IF(BH4=TRUE,BG4," ") -> EN IEC 60598-1:2024 + A11:2024; | BN4: 62031 | BO4: IEC 62031:2018; | BP4: EN 62031:2020 + A11:2021; | BQ4: =OR(Q6,S6,T6) -> #REF! | BR4: =IF(BQ4=TRUE,BO4," ") -> #REF! | BS4: =IF(BQ4=TRUE,BP4," ") -> #REF!
B5: Parte -2 norma: | D5: -2-1 | E5: -2-2 | F5: -2-3 | G5: -2-4 | H5: -2-5 | I5: -2-7 | J5: -2-10 | K5: -2-13 | L5: -2-18 | M5: -2-22 | N5: OTRO | O5: ¿NORMA? | Q5: 62031 (built-in) | R5: 62031 (built-in) | S5: 62031 (indp) | T5: 62031 (integ) | U5: IK (62262) | Z5: PESO GRAL. | AA5: ¿APLICA? | AB5: PESO EN PROY | AC5: ¿FIN? | AD5: PESO FIN. | AH5: PESO GRAL. | AI5: ¿APLICA? | AJ5: PESO EN PROY | AK5: ¿FIN? | AL5: PESO FIN. | AP5: PESO GRAL. | AQ5: ¿APLICA? | AR5: PESO EN PROY | AS5: ¿FIN? | AT5: PESO FIN. | AV5: PESO TOTAL PROYECTO | AX5: =SUM(AB6:AB14,AJ6:AJ14,AR6:AR15) -> #REF! | AY5: =AX5/AX5 -> #REF! | BE5: 60598-2-1 | BF5: IEC 60598-2-1:2020; | BG5: EN IEC 60598-2-1:2021; | BH5: =D6 -> FALSE | BI5: =IF(BH5=TRUE,BF5," ") | BJ5: =IF(BH5=TRUE,BG5," ") | BN5: IK | BO5: IEC 62262:2002+AMD1:2021 + IEC TR 62696:2011; | BP5: EN 62262:2002 + A1:2021 + IEC TR 62696:2011 | BQ5: =U6 -> FALSE | BR5: =IF(BQ5=TRUE,BO5," ") | BS5: =IF(BQ5=TRUE,BP5," ")
D6: FALSE | E6: FALSE | F6: FALSE | G6: FALSE | H6: FALSE | J6: FALSE | K6: FALSE | L6: FALSE | M6: FALSE | N6: FALSE | O6: =OR(D6,E6,F6,G6,H6,J6,K6,L6,M6,S6) -> #REF! | Q6: =#REF! -> #REF! | R6: =#REF! -> #REF! | S6: =#REF! -> #REF! | T6: =#REF! -> #REF! | U6: FALSE | X6: 3. Marcado | Z6: 3 | AA6: =NOT(D38) -> TRUE | AB6: =Z6*AA6 -> 3 | AC6: =NOT(D42) -> FALSE | AD6: =AB6*AC6 -> 0 | AF6: 11. LF y DA | AH6: 5 | AI6: =NOT(BE20) -> TRUE | AJ6: =AH6*AI6 -> 5 | AK6: =NOT(BN28) -> FALSE | AL6: =AJ6*AK6 -> 0 | AN6: 9. IP | AV6: PESO EJECUTADO | AX6: =SUM(AD6:AD14,AL6:AL14,AT6:AT15) -> #REF! | AY6: =AX6/AX5 -> #REF! | BE6: 60598-2-2 | BF6: IEC 60598-2-2:2011/IEC60598-2-2:2023; | BG6: EN 60598-2-2:2012/EN IEC 60598-2-2:2024; | BH6: =E6 -> FALSE | BI6: =IF(BH6=TRUE,BF6," ") | BJ6: =IF(BH6=TRUE,BG6," ")
B7: Muestras: | D7: ='RESUMEN PROYECTO LUM'!D8 -> 1 | F7: NÚM AUTO: | G7: FALSE | H7: NÚM PERSON: | I7: FALSE | X7: 4. Construcción (import.) | AB7: =Z7*AA7 -> 0 | AD7: =AB7*AC7 -> 0 | AF7: 7. Tierra | AH7: 3 | AI7: =NOT(T22) -> TRUE | AJ7: =AH7*AI7 -> 3 | AK7: =NOT(T34) -> FALSE | AL7: =AJ7*AK7 -> 0 | AN7: IP5X/IP6X | AP7: 5 | AQ7: =AV70 -> FALSE | AR7: =AP7*AQ7 -> 0 | AS7: =NOT(AR72) -> FALSE | AT7: =AR7*AS7 -> 0 | AV7: PESO PENDIENTE | AX7: =AX5-AX6 -> #REF! | AY7: =AX7/AX5 -> #REF! | BE7: 60598-2-3 | BF7: IEC 60598-2-3:2002+AMD1:2011; | BG7: EN 60598-2-3:2003+A1:2011; | BH7: =F6 -> FALSE | BI7: =IF(BH7=TRUE,BF7," ") | BJ7: =IF(BH7=TRUE,BG7," ")
B8: Clase: | D8: 1 | X8: 4.6 y 4.7.2 Ensayo vena | Z8: 3 | AA8: =NOT(D77) -> TRUE | AB8: =Z8*AA8 -> 3 | AC8: =NOT(L85) -> FALSE | AD8: =AB8*AC8 -> 0 | AF8: 8. Prot choques electr. | AH8: 3 | AI8: =NOT(AB44) -> TRUE | AJ8: =AH8*AI8 -> 3 | AK8: =NOT(AB56) -> FALSE | AL8: =AJ8*AK8 -> 0 | AN8: IPX_ | AP8: 5 | AQ8: =NOT(AR67) -> TRUE | AR8: =AP8*AQ8 -> 5 | AS8: =NOT(AR62) -> FALSE | AT8: =AR8*AS8 -> 0 | BE8: 60598-2-4 | BF8: IEC 60598-2-4:2017; | BG8: EN 60598-2-4:2018; | BH8: =G6 -> FALSE | BI8: =IF(BH8=TRUE,BF8," ") | BJ8: =IF(BH8=TRUE,BG8," ")
B9: IPX1 | C9: FALSE | D9: IPX3 | E9: FALSE | F9: IPX5 | G9: FALSE | H9: IPX7 | I9: FALSE | J9: IPX9 | K9: FALSE | O9: ¿HAY IPX_? | X9: 4.12 Tornillos, etc | Z9: 3 | AA9: =NOT(D136) -> TRUE | AB9: =Z9*AA9 -> 3 | AC9: =NOT(L154) -> FALSE | AD9: =AB9*AC9 -> 0 | AF9: 12. Calentamientos | AN9: 10.2 Rigidez y Resist. Aisl. | AP9: 5 | AQ9: =NOT(BE47) -> TRUE | AR9: =AP9*AQ9 -> 5 | AS9: =NOT(BE50) -> FALSE | AT9: =AR9*AS9 -> 0 | BE9: 60598-2-5 | BF9: IEC 60598-2-5:2015; | BG9: EN 60598-2-15:2015; | BH9: =H6 -> FALSE | BI9: =IF(BH9=TRUE,BF9," ") | BJ9: =IF(BH9=TRUE,BG9," ") | BN9: TEXTO IEC
B10: IPX2 | C10: FALSE | D10: IPX4 | E10: FALSE | F10: IPX6 | G10: FALSE | H10: IPX8 | I10: FALSE | J10: IPX0 | K10: FALSE | O10: =OR(C9,E9,G9,I9,C10,E10,G10,I10,K9,K10) -> FALSE | X10: 4.13 Impacto | Z10: 3 | AA10: =NOT(D167) -> TRUE | AB10: =Z10*AA10 -> 3 | AC10: =NOT(D171) -> FALSE | AD10: =AB10*AC10 -> 0 | AF10: 12.3 Endurancia | AH10: 100 | AI10: =NOT(AJ41) -> TRUE | AJ10: =AH10*AI10 -> 100 | AK10: =NOT(AJ43) -> FALSE | AL10: =AJ10*AK10 -> 0 | AN10: 10.3 Corrientes de fuga | AP10: 3 | AQ10: =NOT(BE55) -> TRUE | AR10: =AP10*AQ10 -> 3 | AS10: =NOT(BE58) -> FALSE | AT10: =AR10*AS10 -> 0 | BE10: 60598-2-10 | BF10: IEC 60598-2-10:2003; | BG10: EN 60598-2-10:2003; | BH10: =J6 -> FALSE | BI10: =IF(BH10=TRUE,BF10," ") | BJ10: =IF(BH10=TRUE,BG10," ") | BN10: =CONCATENATE(BI4,BI5,BI6,BI7,BI8,BI9,BI10,BI11,BI12,BI13,BI14) -> IEC 60598-1:2024;
B11: IP1X | C11: XXXXX | D11: IP3X | E11: FALSE | F11: IP5X | G11: FALSE | O11: ¿HAY IP_x? | X11: 4.14 Carga | Z11: 3 | AA11: =NOT(L167) -> TRUE | AB11: =Z11*AA11 -> 3 | AC11: =NOT(L171) -> FALSE | AD11: =AB11*AC11 -> 0 | AF11: 12.4 Calentam + tc | AH11: 10 | AI11: =NOT(AJ46) -> TRUE | AJ11: =AH11*AI11 -> 10 | AK11: =NOT(AJ48) -> FALSE | AL11: =AJ11*AK11 -> 0 | AN11: 13. FUEGO | BE11: 60598-2-13 | BF11: IEC 60598-2-13:2006+AMD1:2011+A2:2016; | BG11: EN 60598-2-13:2006+A1:2012+A2:2016+A11:2021; | BH11: =K6 -> FALSE | BI11: =IF(BH11=TRUE,BF11," ") | BJ11: =IF(BH11=TRUE,BG11," ") | BN11: TEXTO EN
B12: IP2X | C12: FALSE | D12: IP4X | E12: FALSE | F12: IP6X | G12: FALSE | O12: =OR(C12,E11,E12,G11,G12) -> FALSE | X12: 4.24 Luz azul | Z12: 5 | AA12: =NOT(D212) -> TRUE | AB12: =Z12*AA12 -> 5 | AC12: =NOT(L213) -> FALSE | AD12: =AB12*AC12 -> 0 | AF12: 12.5 Anormal | AH12: 10 | AI12: =NOT(AJ51) -> TRUE | AJ12: =AH12*AI12 -> 10 | AK12: =NOT(AJ53) -> FALSE | AL12: =AJ12*AK12 -> 0 | AN12: Bola | AP12: 5 | AQ12: =NOT(BW23) -> TRUE | AR12: =AP12*AQ12 -> 5 | AS12: =NOT(BW27) -> FALSE | AT12: =AR12*AS12 -> 0 | BE12: 60598-2-18 | BF12: IEC 60598-2-18:1993+AMD1:2011 ó IEC 60598-2-1+:2022 (ver TRF); | BG12: EN 60598-2-18:1994+A1:2012 ó IEC EN 60598-2-18:2022 (ver TRF); | BH12: =L6 -> FALSE | BI12: =IF(BH12=TRUE,BF12," ") | BJ12: =IF(BH12=TRUE,BG12," ") | BN12: =CONCATENATE(BJ4,BJ5,BJ6,BJ7,BJ8,BJ9,BJ10,BJ11,BJ12,BJ13,BJ14) -> EN IEC 60598-1:2024 + A11:2024;
K13: SELV SI | L13: FALSE | AB13: =Z13*AA13 -> 0 | AD13: =AB13*AC13 -> 0 | AF13: 12.6+12.7 Cond. Fallo | AH13: 10 | AI13: =NOT(AJ56) -> TRUE | AJ13: =AH13*AI13 -> 10 | AK13: =NOT(AJ58) -> FALSE | AL13: =AJ13*AK13 -> 0 | AN13: Llama | AP13: 5 | AQ13: =NOT(BW31) -> TRUE | AR13: =AP13*AQ13 -> 5 | AS13: =NOT(BW43) -> FALSE | AT13: =AR13*AS13 -> 0 | BE13: 60598-2-22 | BF13: IEC 60598-2-22:2021; | BG13: EN IEC 60598-2-22:2022 | BH13: =M6 -> FALSE | BI13: =IF(BH13=TRUE,BF13," ") | BJ13: =IF(BH13=TRUE,BG13," ") | BN13: TEXTO 62031 + IK
B14: IK N/A | C14: FALSE | D14: IK06 | E14: FALSE | F14: IK07 | G14: FALSE | H14: IK08 | I14: FALSE | K14: SELV NO | L14: FALSE | O14: ¿HAY IK INFO? | X14: Partes activa | Z14: 5 | AA14: =NOT(L20) -> TRUE | AB14: =Z14*AA14 -> 5 | AC14: =NOT(L31) -> TRUE | AD14: =AB14*AC14 -> 5 | AF14: IK | AH14: 30 | AI14: =NOT(#REF!) -> #REF! | AJ14: =AH14*AI14 -> #REF! | AK14: =NOT(#REF!) -> #REF! | AL14: =AJ14*AK14 -> #REF! | AN14: Hilo | AP14: 5 | AQ14: =NOT(BW47) -> TRUE | AR14: =AP14*AQ14 -> 5 | AS14: =NOT(BW60) -> FALSE | AT14: =AR14*AS14 -> 0 | BE14: Otro | BF14: {='RESUMEN PROYECTO LUM'!D27:E27} -> 0 | BG14: 0 | BH14: =N6 -> FALSE | BI14: =IF(BH14=TRUE,BF14," ") | BJ14: =IF(BH14=TRUE,BG14," ") | BN14: =CONCATENATE(BR4,BR5," ",BS4,BS5) -> #REF!
B15: IK09 | C15: FALSE | D15: IK10 | E15: FALSE | F15: IK11 (reserv.) | G15: FALSE | K15: ACTIVA SI | L15: FALSE | O15: =OR(C14,E14,G14,I14,C15,E15,G15) -> FALSE | AN15: IRC | AP15: 10 | AQ15: =NOT(BW63) -> TRUE | AR15: =AP15*AQ15 -> 10 | AS15: =NOT(BW70) -> FALSE | AT15: =AR15*AS15 -> 0
K16: ACTIVA NO | L16: FALSE
B18: Ratings y generales | J18: Partes activas | R18: 9. Tierra | Z18: 8. Cableado | AH18: 14. Calentamiento | AP18: 11. IP | BC18: 12. Rigidez / Resist. Aislam / Corrientes fuga | BL18: 13. LF y DA | BU18: 15. Resistencia al fuego | CD18: 60598-2-3
B20: N/A | E20: Si es verdadero el apartado no aplica | J20: N/A | L20: FALSE | M20: Si es verdadero el apartado no aplica | R20: N/A Checkbox | T20: FALSE | U20: Verifica si se ha marcado la casilla N/A | Z20: N/A Checkbox sección | AB20: FALSE | AC20: Verifica si se ha marcado la casilla N/A | AH20: N/A Checkbox sección | AJ20: FALSE | AK20: Verifica si se ha marcado la casilla N/A | AP20: N/A Checkbox sección | AR20: FALSE | AS20: Verifica si se ha marcado la casilla N/A | BC20: N/A Checkbox sección | BE20: FALSE | BL20: N/A Checkbox sección | BN20: FALSE | BU20: N/A Checkbox sección | BW20: FALSE | CD20: Aplica esta parte -2 | CF20: =F6 -> FALSE | CL20: FALTAN DATOS EN ALGUNA PARTE -2 | CO20: =OR(CF60,CF75,CM85,CM96,CF108) -> FALSE
B21: ¿Hace falta tamaño? | D21: =OR(E9,E10) -> FALSE | E21: (Dato necesario para IPX3 e IPX4) | J21: ¿SELV? | L21: =L13 -> FALSE | M21: =IF(L13=L14,1,0) -> 1 | N21: (Comprueba la checklist de SELV) | R21: N/A porque es clase II | T21: =IF(D8<>1,TRUE,FALSE) -> FALSE | U21: Verifica si la luminaria es clase II y por tanto no aplica
B22: Datos necesarios | D22: =IF(OR(D21=FALSE),0,3*D7) -> 0 | E22: (3 por muestra) | J22: ¿Parte activa? | L22: =L15 -> FALSE | M22: =IF(L21=TRUE,0,IF(L15=L16,1,0)) -> 1 | N22: (Si no es SELV, entoces comprueba checklist de parte activa) | R22: N/A Total sección | T22: =OR(T20,T21) -> FALSE | U22: Unifica los dos criterios anteriores | Z22: N/A Dispositivo anclaje | AB22: FALSE | AH22: LUGARES DE ENSAYO: | AK22: Son verdaderos los equipos marcados | AP22: Radios disponibles: | AR22: 20 | AS22: 40 | AT22: 60 | AU22: 80 | AV22: 100 | AW22: 120 | AX22: 140 | AY22: cm | BC22: Equipos utilizados | BL22: N/A Checkbox tabla 1 | BN22: FALSE | BU22: N/A Bola | BW22: FALSE | CD22: Carga estática N/A | CF22: FALSE
B23: Datos rellenos | D23: =COUNTIF('Toma de notas 60598'!G17:N19,">0") -> 0 | E23: (cuenta cuantos datos se han introducido) | Z23: Warning Fecha | AB23: =IF('Toma de notas 60598'!F595=0,1,0) -> 1 | AC23: Si vale 1 falta por introducir la fecha | AH23: EQ-SAFE-301 | AJ23: FALSE | BE23: RES. AISLM. | BF23: RIGIDEZ | BG23: CORR FUGA | BH23: RESUMEN | BL23: N/A Checkbox tabla 2 | BN23: FALSE | BU23: N/A Sección bola | BW23: =OR(BW20,BW22) -> FALSE | BX23: Comprueba si la sección + ensayo aplican | CD23: Carga estática conjto N/A | CF23: =OR(CF22,NOT(CF20)) -> TRUE | CG23: Verifica con la parte 2
B24: Datos pendientes | D24: =D22-D23 -> 0 | E24: (cuenta datos pendientes) | J24: Datos necesarios | L24: =IF(L21=TRUE,0,3*D7) -> 3 | M24: (3 por muestra) | R24: Warning Fecha | T24: =IF('Toma de notas 60598'!F575=0,1,0) -> 1 | U24: Si vale 1 falta por introducir la fecha | AH24: EQ-SAFE-302 | AJ24: FALSE | AQ24: Muestra01 | AR24: Muestra02 | AS24: Muestra03 | AT24: Muestra04 | AU24: Muestra05 | AV24: Muestra06 | AW24: Muestra07 | AX24: Muestra08 | BC24: EQ-SAFE-403 (GPT-15004) | BE24: TRUE | BF24: TRUE | BG24: FALSE | BH24: =OR(BE24,BF24,BG24) -> TRUE
B25: Warning texto aviso | D25: =IF(AND(D24<>0,D21=TRUE),1,0) -> 0 | E25: Si vale 1 aparece texto aviso | J25: Datos rellenos | L25: =COUNTIF('Toma de notas 60598'!G31:N33,">0") -> 3 | M25: (cuenta cuantos datos se han introducido) | Z25: Faltan datos disp. Anclaje | AB25: =IF(AB22=TRUE,FALSE,IF(AB23=1,TRUE,FALSE)) -> TRUE | AH25: EQ-SAFE-328 | AJ25: FALSE | AP25: Alto (H) cm | AQ25: =IF($E$10,'Toma de notas 60598'!G17/2,'Toma de notas 60598'!G17) -> 0 | AR25: ='Toma de notas 60598'!H17 -> 0 | AS25: ='Toma de notas 60598'!I17 -> 0 | AT25: ='Toma de notas 60598'!J17 -> 0 | AU25: ='Toma de notas 60598'!K17 -> 0 | AV25: ='Toma de notas 60598'!L17 -> 0 | AW25: ='Toma de notas 60598'!M17 -> 0 | AX25: ='Toma de notas 60598'!N17 -> 0 | BC25: EQ-SAFE-404 (GLC-1000) | BE25: FALSE | BF25: FALSE | BG25: FALSE | BH25: =OR(BE25,BF25,BG25) -> FALSE | BL25: Warning fecha | BN25: =IF('Toma de notas 60598'!F540=0,1,0) -> 1 | BO25: Vale 1 si no hay fecha indicada | BU25: Warning fecha bola | BW25: =IF('Toma de notas 60598'!F846=0,1,0) -> 1 | BX25: Vale 1 si no hay fecha indicada | CD25: Algura carga estática | CF25: Menor 8m | CG25: Entre 8-15m | CH25: Mayor 15m
J26: Datos pendientes | L26: =L24-L25 -> 0 | R26: Datos de ensayo | T26: =IF(COUNTIF('Toma de notas 60598'!G577:N577,">0")>1,TRUE,FALSE) -> FALSE | U26: No se usa porque pueden tomarse directamente sobre el TRF | AH26: EQ-SAFE-303 | AJ26: FALSE | AP26: Ancho (A)cm | AQ26: ='Toma de notas 60598'!G18 -> 0 | AR26: ='Toma de notas 60598'!H18 -> 0 | AS26: ='Toma de notas 60598'!I18 -> 0 | AT26: ='Toma de notas 60598'!J18 -> 0 | AU26: ='Toma de notas 60598'!K18 -> 0 | AV26: ='Toma de notas 60598'!L18 -> 0 | AW26: ='Toma de notas 60598'!M18 -> 0 | AX26: ='Toma de notas 60598'!N18 -> 0 | BC26: EQ-SAFE-402 (GPT-15002) | BE26: FALSE | BF26: FALSE | BG26: FALSE | BH26: =OR(BE26,BF26,BG26) -> FALSE | CF26: FALSE | CG26: FALSE | CH26: FALSE
B27: Warning Fecha | D27: =IF('Toma de notas 60598'!F5>0,0,1) -> 1 | E27: Si vale 1 falta por introducir la fecha | J27: Warining texto aviso | L27: =IF(L26>0,1,0) -> 0 | M27: Si vale 1 aparece texto aviso | R27: Equipo utilizado: | Z27: N/A cable secc pequeña | AB27: FALSE | AH27: AMPLIACIÓN 2 | AK27: No está asignado todavía | AP27: Profundo (P) cm | AQ27: ='Toma de notas 60598'!G19 -> 0 | AR27: ='Toma de notas 60598'!H19 -> 0 | AS27: ='Toma de notas 60598'!I19 -> 0 | AT27: ='Toma de notas 60598'!J19 -> 0 | AU27: ='Toma de notas 60598'!K19 -> 0 | AV27: ='Toma de notas 60598'!L19 -> 0 | AW27: ='Toma de notas 60598'!M19 -> 0 | AX27: ='Toma de notas 60598'!N19 -> 0 | BC27: EQ-SAFE-441 (AINUO) | BE27: FALSE | BF27: FALSE | BG27: TRUE | BH27: =OR(BE27,BF27,BG27) -> TRUE | BU27: Faltan datos bola | BW27: =IF(BW23=TRUE,FALSE,IF(OR(BW25=1,NOT(BU125)),TRUE,FALSE)) -> TRUE | CD27: ¿Marcado 1 o ninguna? | CF27: =COUNTIF(CF26:CH26,"VERDADERO") -> 0
R28: EQ-SAFE-442 (Elabo) | T28: TRUE | Z28: Warning Fecha | AB28: =IF('Toma de notas 60598'!F610=0,1,0) -> 1 | AC28: Si vale 1 falta por introducir la fecha | BC28: RESERVADO COPPER-BS | BE28: FALSE | BF28: FALSE | BG28: FALSE | BH28: =OR(BE28,BF28,BG28) -> FALSE | BL28: FALTAN DATOS SECCIÓN | BN28: =IF(BN20=TRUE,FALSE,IF(AND(BN22=TRUE,BN23=TRUE),FALSE,IF(BN25=1,TRUE,FALSE))) -> TRUE | BY28: 13.2.1 | BZ28: BOLA CONTINÚA ABAJO | CD28: Velocidad viento (m/s) | CF28: {=_xlfn.IFS(CF26=TRUE,45,CG26=TRUE,52,CH26=TRUE,57,CI26=0,0)} -> 0
B29: Faltan datos en sección | D29: =OR(D25,D27) -> TRUE | E29: (Comprueba si está fecha y si hay datos IP) | J29: Warning Fecha | L29: =IF('Toma de notas 60598'!F26,0,1) -> 0 | M29: Si vale 1 falta por introducir la fecha | R29: EQ-SAFE-403 (GW INSTEK) (Bussmann) | T29: FALSE | Z29: Comprobación checkbox | AH29: Al menos un lugar elegido | AJ29: =OR(AJ23,AJ24,AJ25,AJ26,AJ27) -> FALSE | AP29: d1 | AQ29: =SQRT((AQ26/2)^2+(AQ27/2)^2) -> 0 | AR29: =SQRT((AR26/2)^2+(AR27/2)^2) -> 0 | AS29: =SQRT((AS26/2)^2+(AS27/2)^2) -> 0 | AT29: =SQRT((AT26/2)^2+(AT27/2)^2) -> 0 | AU29: =SQRT((AU26/2)^2+(AU27/2)^2) -> 0 | AV29: =SQRT((AV26/2)^2+(AV27/2)^2) -> 0 | AW29: =SQRT((AW26/2)^2+(AW27/2)^2) -> 0 | AX29: =SQRT((AX26/2)^2+(AX27/2)^2) -> 0 | BC29: PREVISIÓN 1 | BE29: FALSE | BF29: FALSE | BG29: FALSE | BH29: =OR(BE29,BF29,BG29) -> FALSE | CD29: Cálculo fuerza (N) | CF29: =0.5*1.225*'Toma de notas 60598'!G382*1.2*'Datos ensayos LUM.'!$CF$28^2 -> 0 | CG29: =0.5*1.225*'Toma de notas 60598'!H382*1.2*'Datos ensayos LUM.'!$CF$28^2 -> 0 | CH29: =0.5*1.225*'Toma de notas 60598'!I382*1.2*'Datos ensayos LUM.'!$CF$28^2 -> 0 | CI29: =0.5*1.225*'Toma de notas 60598'!J382*1.2*'Datos ensayos LUM.'!$CF$28^2 -> 0 | CJ29: =0.5*1.225*'Toma de notas 60598'!K382*1.2*'Datos ensayos LUM.'!$CF$28^2 -> 0 | CK29: =0.5*1.225*'Toma de notas 60598'!L382*1.2*'Datos ensayos LUM.'!$CF$28^2 -> 0 | CL29: =0.5*1.225*'Toma de notas 60598'!M382*1.2*'Datos ensayos LUM.'!$CF$28^2 -> 0 | CM29: =0.5*1.225*'Toma de notas 60598'!N382*1.2*'Datos ensayos LUM.'!$CF$28^2 -> 0
Z30: FALSE | AA30: FALSE | AP30: d | AQ30: =SQRT(AQ25^2+AQ29^2) -> 0 | AR30: =SQRT(AR25^2+AR29^2) -> 0 | AS30: =SQRT(AS25^2+AS29^2) -> 0 | AT30: =SQRT(AT25^2+AT29^2) -> 0 | AU30: =SQRT(AU25^2+AU29^2) -> 0 | AV30: =SQRT(AV25^2+AV29^2) -> 0 | AW30: =SQRT(AW25^2+AW29^2) -> 0 | AX30: =SQRT(AX25^2+AX29^2) -> 0 | BC30: PREVISIÓN 2 | BE30: FALSE | BF30: FALSE | BG30: FALSE | BH30: =OR(BE30,BF30,BG30) -> FALSE | BU30: N/A Llama aguja | BW30: FALSE
J31: Faltan datos en sección | L31: =IF(L20=TRUE,FALSE,OR(L27,L29)) -> FALSE | M31: (Comprueba si está fecha y si hay datos IP) | R31: Equipamiento selecc. | T31: =OR(T28,T29) -> TRUE | Z31: RESULTADO | AB31: =AND(Z30,AA30) -> FALSE | AH31: EQUIPOS DE ENSAYO | BU31: N/A sección Llama aguja | BW31: =OR(BW20,BW30) -> FALSE | BX31: Comprueba si la sección + ensayo aplican | CD31: Warning fecha | CF31: =IF('Toma de notas 60598'!F380=0,1,0) -> 1 | CG31: Vale 1 si no hay fecha
Z32: Faltan datos en sec peq | AB32: =IF(AB27=TRUE,FALSE,IF(OR(AB28=1,AB31=FALSE),TRUE,FALSE)) -> TRUE | AH32: EQ-SAFE-327 (recuperado) | AJ32: =AJ23 -> FALSE | AP32: R máx (cm) | AQ32: =AQ30+20 -> 20 | AR32: =AR30+20 -> 20 | AS32: =AS30+20 -> 20 | AT32: =AT30+20 -> 20 | AU32: =AU30+20 -> 20 | AV32: =AV30+20 -> 20 | AW32: =AW30+20 -> 20 | AX32: =AX30+20 -> 20 | AY32: Radio máximo del arco =d+20cm | BC32: ¿Hay equipos seleccionados? | BE32: =OR(BE24,BE25,BE26,BE27,BE28,BE29,BE30) -> TRUE | BF32: =OR(BF24,BF25,BF26,BF27,BF28,BF29,BF30) -> TRUE | BG32: =OR(BG24,BG25,BG26,BG27,BG28,BG29,BG30) -> TRUE | BH32: =OR(BH24,BH25,BH26,BH27,BH28,BH29,BH30) -> TRUE
AH33: EQ-SAFE-3xx | AI33: (recuperado) | AJ33: =AJ24 -> FALSE | AP33: RADIO ENSAYO | AQ33: {=IF(AQ32=20,"N/A",_xlfn.IFS($AX$22<AQ32,"Cab. Regadera",$AW$22<AQ32,$AW$22,$AV$22<=AQ32,$AV$22,$AU$22<=AQ32,$AU$22,$AT$22<=AQ32,$AT$22,$AS$22<=AQ32,$AS$22,$AR$22<=AQ32,$AR$22))} -> N/A | AR33: {=IF(AR32=20,"N/A",_xlfn.IFS($AX$22<AR32,"Cab. Regadera",$AW$22<AR32,$AW$22,$AV$22<=AR32,$AV$22,$AU$22<=AR32,$AU$22,$AT$22<=AR32,$AT$22,$AS$22<=AR32,$AS$22,$AR$22<=AR32,$AR$22))} -> N/A | AS33: {=IF(AS32=20,"N/A",_xlfn.IFS($AX$22<AS32,"Cab. Regadera",$AW$22<AS32,$AW$22,$AV$22<=AS32,$AV$22,$AU$22<=AS32,$AU$22,$AT$22<=AS32,$AT$22,$AS$22<=AS32,$AS$22,$AR$22<=AS32,$AR$22))} -> N/A | AT33: {=IF(AT32=20,"N/A",_xlfn.IFS($AX$22<AT32,"Cab. Regadera",$AW$22<AT32,$AW$22,$AV$22<=AT32,$AV$22,$AU$22<=AT32,$AU$22,$AT$22<=AT32,$AT$22,$AS$22<=AT32,$AS$22,$AR$22<=AT32,$AR$22))} -> N/A | AU33: {=IF(AU32=20,"N/A",_xlfn.IFS($AX$22<AU32,"Cab. Regadera",$AW$22<AU32,$AW$22,$AV$22<=AU32,$AV$22,$AU$22<=AU32,$AU$22,$AT$22<=AU32,$AT$22,$AS$22<=AU32,$AS$22,$AR$22<=AU32,$AR$22))} -> N/A | AV33: {=IF(AV32=20,"N/A",_xlfn.IFS($AX$22<AV32,"Cab. Regadera",$AW$22<AV32,$AW$22,$AV$22<=AV32,$AV$22,$AU$22<=AV32,$AU$22,$AT$22<=AV32,$AT$22,$AS$22<=AV32,$AS$22,$AR$22<=AV32,$AR$22))} -> N/A | AW33: {=IF(AW32=20,"N/A",_xlfn.IFS($AX$22<AW32,"Cab. Regadera",$AW$22<AW32,$AW$22,$AV$22<=AW32,$AV$22,$AU$22<=AW32,$AU$22,$AT$22<=AW32,$AT$22,$AS$22<=AW32,$AS$22,$AR$22<=AW32,$AR$22))} -> N/A | AX33: {=IF(AX32=20,"N/A",_xlfn.IFS($AX$22<AX32,"Cab. Regadera",$AW$22<AX32,$AW$22,$AV$22<=AX32,$AV$22,$AU$22<=AX32,$AU$22,$AT$22<=AX32,$AT$22,$AS$22<=AX32,$AS$22,$AR$22<=AX32,$AR$22))} -> N/A | AY33: Elegimos tamaño arco por debajo | BU33: Warning fecha aguja | BW33: =IF('Toma de notas 60598'!F910=0,1,0) -> 1 | BX33: Vale 1 si no hay fecha indicada | CD33: Faltan datos carga estát. | CF33: =IF(CF23=TRUE,FALSE,IF(OR(CF31=1,CF27<>1),TRUE,FALSE)) -> FALSE | CK33: 60598-2-5
R34: Faltan datos en sección | T34: =IF(T22=TRUE,FALSE,IF(OR(T24=1,T31=FALSE),TRUE,FALSE)) -> TRUE | AH34: EQ-SAFE-323 | AI34: (nuevo) | AJ34: FALSE | BC34: ¿Portatil clase I? | BE34: =AND(G6,D8=1) -> FALSE | BF34: Revisamos si es necesario usar kikusui para corientes de fuga
AH35: EQ-SAFE-324(nuevo) | AJ35: FALSE | AP35: ¿Es IPX3 ó IPX4? | AR35: =OR(E9,E10) -> FALSE | AT35: ¿Cab. Regadera? | AV35: =IF(COUNTIF(AQ33:AX33,"Cab. Regadera")>0,TRUE,FALSE) -> FALSE | BU35: Checklist aguja | CK35: Aplica esta parte -2 | CM35: =H6 -> FALSE
B36: 6. Marcado | J36: 4. RESUMEN GENERAL DE SECCIÓN 4 | Z36: Faltan datos subclauses | AB36: =OR(AB25,AB32) -> TRUE | AH36: AMPLIACIÓN 1 | AK36: No está asignado todavía | AP36: ¿Hay dimensiones? | AR36: =IF(COUNTIF(AQ25:AX27,">0")>=3,TRUE,FALSE) -> FALSE | BV36: 1 | BW36: =BU134 -> FALSE | BX36: El valor viene de la VERIFICACIÓN DE 24 HORAS QUE HAY MÁS ABAJO | CD36: Rotura N/A | CF36: FALSE
Z37: Faltan datos en sección | AB37: =IF(AB20=TRUE,FALSE,IF((AB36=TRUE),TRUE,FALSE)) -> TRUE | AH37: AMPLIACIÓN 2 | AK37: No está asignado todavía | BC37: Resistencia de aislamiento | BV37: 2 | BW37: FALSE | CD37: Rotura conjunto N/A | CF37: =OR(CF36,NOT(CF20)) -> TRUE | CG37: Verifica con la parte 2 | CK37: Carga estática N/A | CM37: FALSE
B38: N/A | D38: FALSE | E38: Si es verdadero el apartado no aplica | K38: N/A | L38: FALTAN DATOS | BC38: N/A aislamiento | BE38: FALSE | BF38: Verifica si aplica esta subclause | BV38: 3 | BW38: FALSE | CK38: Carga estática conjto N/A | CM38: =OR(CM37,NOT(CM35)) -> TRUE
J39: 7 Completa | K39: FALSE | L39: =OR(L40,L41,L42,L43,L44,L48,L50,L51,L52,L53,L54,L56,L58) -> TRUE | M39: Cuando se incorporen las partes -2 habrá quea añadir más casillas al "Y" | AH39: Al menos un eq. Elegido | AJ39: =OR(AJ32,AJ33,AJ34,AJ35,AJ36,AJ37) -> FALSE | AP39: Información a trasladar a la toma de datos: | BC39: N/A subclause | BE39: =OR(BE38,BE20) -> FALSE | BF39: Combina subclause con apartado completo | BL39: 16 y 17 Bornes | BV39: 4 | BW39: FALSE | CD39: Warning fecha | CF39: =IF('Toma de notas 60598'!F390=0,1,0) -> 1 | CG39: Vale 1 si no hay fecha
B40: Warning Fecha | D40: =IF('Toma de notas 60598'!F45=0,1,0) -> 1 | E40: Si vale 1 falta por introducir la fecha | J40: 7.4 | K40: FALSE | L40: =D66 -> TRUE | AQ40: Muestra01 | AR40: Muestra02 | AS40: Muestra03 | AT40: Muestra04 | AU40: Muestra05 | AV40: Muestra06 | AW40: Muestra07 | AX40: Muestra08 | BC40: Warning fecha | BE40: =IF('Toma de notas 60598'!$F$773=0,1,0) -> 1 | BF40: Vale 1 si no hay fecha indicada | BV40: 5 | BW40: FALSE | CK40: Warning fecha | CM40: =IF('Toma de notas 60598'!F425=0,1,0) -> 1
J41: 7.6 Y 7.7 | K41: FALSE | L41: =L85 -> TRUE | AH41: N/A Endurancia | AJ41: FALSE | AK41: Verifica si se ha aplicado el apartado | AP41: INFO: | AQ41: =IF($AR$35=TRUE,AQ33,"N/A") -> N/A | AR41: =IF($AR$35=TRUE,AR33,"N/A") -> N/A | AS41: =IF($AR$35=TRUE,AS33,"N/A") -> N/A | AT41: =IF($AR$35=TRUE,AT33,"N/A") -> N/A | AU41: =IF($AR$35=TRUE,AU33,"N/A") -> N/A | AV41: =IF($AR$35=TRUE,AV33,"N/A") -> N/A | AW41: =IF($AR$35=TRUE,AW33,"N/A") -> N/A | AX41: =IF($AR$35=TRUE,AX33,"N/A") -> N/A | BL41: N/A Checkbox 14 ni 15 | BN41: FALSE | BP41: FALTAN DATOS 14 Y 15 | BR41: =OR(BN54,BN77) -> TRUE | BU41: TOTAL | BW41: =AND(BW36,BW37,BW38,BW39,BW40) -> FALSE | BX41: Revisa que estén todas las opciones marcadas. FALSO si no están marcados | CD41: Faltan datos Rotura | CF41: =IF(CF37=TRUE,FALSE,IF(CF39=1,TRUE,FALSE)) -> FALSE | CK41: Warning datos tamaño | CM41: =IF(COUNTIF('Toma de notas 60598'!G427:N427,">0")=0,1,0) -> 1 | CN41: Revisa si hay datos de tamaño
B42: Faltan datos en sección | D42: =IF(D38=TRUE,FALSE,IF(D40=1,TRUE,FALSE)) -> TRUE | E42: (Comprueba si está fecha y si el apartado aplica) | J42: 7.9 | K42: FALSE | L42: =D112 -> FALSE | Z42: 10. Protección contra choque eléctrico | AH42: Warning fecha endurancia | AJ42: =IF(AND('Toma de notas 60598'!$F$662=0,'Toma de notas 60598'!G661=0),1,0) -> 1 | AK42: Si vale 1 falta por introducir la fecha (tiene también en cuenta la de la muestra 1) | BC42: Faltan datos aislamiento | BE42: =IF(BE39=TRUE,FALSE,IF(OR(BE40=1,BE32=FALSE),TRUE,FALSE)) -> TRUE
J43: 7.10 | K43: FALSE | L43: =L85 -> TRUE | AH43: Faltan datos endurancia | AJ43: =IF(AJ41=TRUE,FALSE,IF(AJ42=1,TRUE,FALSE)) -> TRUE | BL43: SECCIÓN 164 TORNILLO | BU43: Faltan datos aguja | BW43: =IF(BW31=TRUE,FALSE,IF(OR(BW33=1,BW41=FALSE,NOT(BU145)),TRUE,FALSE)) -> TRUE | CK43: Faltan datos carga estát. | CM43: =IF(CM38=TRUE,FALSE,IF(OR(CM40=1,CM41=1),TRUE,FALSE)) -> FALSE
...

Sheet Índice
C3: 3. Marcado | F3: TRUE
D4: 3.4. Verificación del marcado | F4: TRUE
C5: 4. Construcción | F5: TRUE
D6: 4.4. Portalámparas | F6: =F$5 -> TRUE
D7: 4.6. Bloques de conexión | F7: =F$5 -> TRUE
D8: 4.7.2. Bornes y conexiones a la red de alimentación | F8: =F$5 -> TRUE
D9: 4.9. Revestimientos y manguitos aislantes | F9: =F$5 -> TRUE
G11: 2
E13: RIGIDEZ
G14: 1
E16: RESISTENCIA AISLAMIENTO
G17: 1
D20: 4.10. Aislamiento doble o reforzado | F20: =F$5 -> TRUE
D21: 4.12. Tornillos y conexiones mecánicas y prensaestopas | F21: =F$5 -> TRUE
D22: 4.13. Ensayo de golpe martillo impacto | F22: =F$5 -> TRUE
D23: 4.14. Suspensiones, fiaciones y dispositivos de regulación | F23: =F$5 -> TRUE
D24: 4.18. Resistencia a la corrosión | F24: =F$5 -> TRUE
G28: 1
D31: 4.24.2. Riesgo retiniano de luz azul | F31: =F$5 -> TRUE
D32: 4.28. Fijación de los dispositivos de control sensibles a la temperatura | F32: =F$5 -> TRUE
C33: 7. Continuidad circuito tierra | F33: TRUE
G36: 2
C39: 9. Resistencia a la penetración de polvo, objetos sólidos y a la humedad | F39: TRUE
D40: 9.3. Ensayos de IP y humedad | F40: =F39 -> TRUE
G43: 2
G46: 2
C47: 5. Cableado externo e interno | F47: TRUE
D48: 5.2 Cableado interno | F48: =F47 -> TRUE
C49: 8. Protección contra coche eléctrico | F49: TRUE
G53: 3
C55: 10. Resistencia del aislamiento y fuerza eléctrica | F55: TRUE
D56: 10.2.1. Resistencia de aislamiento | F56: TRUE
G59: 2
D61: 10.2.2. Rigidez dieléctrica | F61: TRUE
G62: 2
D66: 10.3. Corrientes de fuga | F66: TRUE
G68: 2
G70: 3
C71: 11. Distancias de fuga y distancias de aislamiento | F71: TRUE
D72: 11.2. Líneas de fuga y distancias en el aire | F72: =F71 -> TRUE
...

Sheet Equipos
B6: 3. MARCADO | F6: 4. CONSTRUCCIÓN | AH6: =Índice!C55 -> 10. Resistencia del aislamiento y fuerza eléctrica | AT6: 13. Resistencia al calor, al fuego y a la formación de caminos conductores
C8: {=IF('Toma de notas 60598'!F45<>0,'BBDD Equipos 60598'!C6:D9,"NO ENSAYADO")} -> NO ENSAYADO | G8: 4.4. Portalámparas | K8: =Índice!D20 -> 4.10. Aislamiento doble o reforzado | O8: =Índice!D24 -> 4.18. Resistencia a la corrosión | S8: =Índice!C33 -> 7. Continuidad circuito tierra | W8: =Índice!D40 -> 9.3. Ensayos de IP y humedad | AA8: =Índice!D48 -> 5.2 Cableado interno | AE8: =Índice!C49 -> 8. Protección contra coche eléctrico | AI8: =Índice!D56 -> 10.2.1. Resistencia de aislamiento | AM8: =Índice!D72 -> 11.2. Líneas de fuga y distancias en el aire | AQ8: =Índice!C73 -> 12. Endurancia/Calentamientos
G9: {=IF(Índice!F6=TRUE,'BBDD Equipos 60598'!G6:H12,"NO ENSAYADO")} -> EQ-SAFE-213 | H9: Dinamómetro | K9: {=IF(Índice!F20=TRUE,'BBDD Equipos 60598'!G46:H51,"NO ENSAYADO")} -> EQ-SAFE-601 | L9: Indicador de contacto eléctr. | N9: =IF('Datos ensayos LUM.'!C190<>2,"X","") -> X | O9: {=IF(Índice!F24=TRUE,'BBDD Equipos 60598'!G81:H88,"NO ENSAYADO")} -> EQ-SAFE-305 | P9: Estufa | R9: =IF('Datos ensayos LUM.'!T28=TRUE,"X","") -> X | S9: {=IF(Índice!F33=TRUE,'BBDD Equipos 60598'!O6:P11,"NO ENSAYADO")} -> EQ-SAFE-442 | T9: Medidor de continuidad de tierra (ELABO) | V9: =IF('Datos ensayos LUM.'!AR47=TRUE,"X","") | W9: {=IF(Índice!F40=TRUE,'BBDD Equipos 60598'!AE6:AF37,"NO ENSAYADO")} -> EQ-SAFE-174 + EQ-SAFE-210 | X9: Arco de lluvia + Caudalímetro | AA9: {=IF(Índice!F48=TRUE,'BBDD Equipos 60598'!S6:T9,"NO ENSAYADO")} -> EQ-SAFE-213 | AB9: Dinamómetro | AE9: {=IF(Índice!F49=TRUE,'BBDD Equipos 60598'!W6:X18,"NO ENSAYADO")} -> EQ-SAFE-122 | AF9: Dedo de prueba normalizado | AH9: =IF('Datos ensayos LUM.'!BE26=TRUE,"X","") | AI9: {=IF(Índice!F56=TRUE,'BBDD Equipos 60598'!AI6:AJ11,"NO ENSAYADO")} -> EQ-SAFE-403 | AJ9: Medidor resistencia de aislamiento (GW INSTEK) | AM9: {=IF(Índice!F72=TRUE,'BBDD Equipos 60598'!K6:L16,"NO ENSAYADO")} -> EQ-SAFE-207 | AN9: Micrómetro | AP9: =IF('Datos ensayos LUM.'!AJ23=TRUE,"X","") | AQ9: {=IF(Índice!F73=TRUE,'BBDD Equipos 60598'!AA6:AB18,"NO ENSAYADO")} -> EQ-SAFE-301 | AR9: Cámara panelable | AU9: =Índice!D89 -> 13.2. Resistencia al calor | AY9: =Índice!C96 -> Anexo A (Partes activas)
G10: EQ-SAFE-216 | H10: Llave dinamométrica | K10: EQ-SAFE-113 | L10: Punzón cónico | N10: =IF('Datos ensayos LUM.'!C190=2,"X","") | O10: EQ-SAFE-330 | P10: Cámara climática | R10: =IF('Datos ensayos LUM.'!T29=TRUE,"X","") | S10: EQ-SAFE-403 | T10: Medidor de continuidad de tierra (GW INSTEK.) | V10: =IF('Datos ensayos LUM.'!AR48=TRUE,"X","") | W10: EQ-SAFE-105 | X10: Boquillas | AA10: EQ-SAFE-235 EQ-SAFE-236 | AB10: Llave dinamométrica hasta 4 N.m Llave dinamométrica entre 4 N.m y 40N.m | AE10: EQ-SAFE-107 | AF10: Sonda 50mm diámetro | AH10: =IF('Datos ensayos LUM.'!BE28=TRUE,"X","") | AI10: EQ-SAFE-403 | AJ10: Medidor resistencia de aislamiento (GW INSTEK) | AM10: EQ-SAFE-206 | AN10: Pie de rey | AP10: =IF('Datos ensayos LUM.'!AJ24=TRUE,"X","") | AQ10: EQ-SAFE-302 | AR10: Cámara panelable | AU10: {=IF(Índice!F89=TRUE,'BBDD Equipos 60598'!AM6:AN18,"NO ENSAYADO")} -> EQ-SAFE-305 | AV10: Estufa | AX10: =IF(Índice!$G$99=1,"X","") | AY10: {=IF(Índice!F96=TRUE,'BBDD Equipos 60598'!AU6:AV16,"NO ENSAYADO")} -> EQ-SAFE-417 | AZ10: Multimetro UNI-T
G11: EQ-SAFE-206 | H11: Pie de rey | K11: EQ-SAFE-311; EQ-SAFE-312; EQ-SAFE-313 | L11: Termohigrómetros | O11: RC-SAFE-001 | P11: Cloruro de amonio | S11: EQ-SAFE-311; EQ-SAFE-312; EQ-SAFE-313 | T11: Termohigrómetros | V11: =IF('Datos ensayos LUM.'!AR46=TRUE,"X","") | W11: EQ-SAFE-111 | X11: Cabeza de regadera (si R necesario > 120cm) | AA11: EQ-SAFE-311; EQ-SAFE-312; EQ-SAFE-313 | AB11: Termohigrómetros | AD11: =IF('Datos ensayos LUM.'!AB49=TRUE,"X","") | AE11: EQ-SAFE-437 | AF11: Multimetro UNI-T | AI11: EQ-SAFE-311; EQ-SAFE-312; EQ-SAFE-313 | AJ11: Termohigrómetros | AM11: EQ-SAFE-212 | AN11: Flexómetro | AP11: =IF('Datos ensayos LUM.'!AJ25=TRUE,"X","") | AQ11: EQ-SAFE-328 | AR11: Estufa endurancias DYCOMETAL | AT11: =IF(Índice!$G$91=1,"X","") | AU11: EQ-SAFE-328 | AV11: Registrador | AX11: =IF(Índice!$G$99=2,"X","") | AY11: EQ-SAFE-428 | AZ11: Multímetro Fluke
G12: EQ-SAFE-207 | H12: Micrómetro digital | K12: Otros: | L12: 0 | O12: EQ-SAFE-311; EQ-SAFE-312; EQ-SAFE-313 | P12: Termohigrómetros | S12: Otros: | T12: 0 | V12: =IF('Datos ensayos LUM.'!AR49=TRUE,"X","") | W12: EQ-SAFE-608 | X12: Depósitos de inmersión | AA12: EQ-SAFE-606 | AB12: Zumbador Fig. 34 IEC 60598-1:2020 | AD12: =IF('Datos ensayos LUM.'!AB50=TRUE,"X","") | AE12: EQ-SAFE-428 | AF12: Multímetro Fluke | AI12: Otros: | AJ12: 0 | AM12: EQ-SAFE-605 | AN12: Lámina cinta 0,1-2,00mm | AP12: =IF('Datos ensayos LUM.'!AJ32=TRUE,"X","") | AQ12: EQ-SAFE-303 | AR12: Cámara climática (3) | AU12: EQ-SAFE-323 | AV12: Registrador 20 canales Graphtec | AX12: =IF(Índice!$G$99=3,"X","") -> X | AY12: EQ-SAFE-430 | AZ12: Multímetro/Pinza UNI-T
G13: EQ-SAFE-311; EQ-SAFE-312; EQ-SAFE-313 | H13: Termohigrómetros | K13: 0 | L13: 0 | O13: EQ-SAFE-407 | P13: Cronómetro digital | S13: 0 | T13: 0 | V13: =IF('Datos ensayos LUM.'!AR45=TRUE,"X","") | W13: EQ-SAFE-615 | X13: Caja de goteo | AD13: =IF('Datos ensayos LUM.'!AB51=TRUE,"X","") | AE13: EQ-SAFE-430 | AF13: Multímetro/Pinza UNI-T | AI13: 0 | AJ13: 0 | AM13: EQ-SAFE-167 | AN13: Juego de galgas | AP13: =IF('Datos ensayos LUM.'!AJ33=TRUE,"X","") | AQ13: EQ-SAFE-327 | AR13: Medidor temperatura 40 canales | AT13: =IF(Índice!$G$91=3,"X","") | AU13: EQ-SAFE-324 | AV13: Registrador 20 canales Graphtec (Maletín) | AX13: =IF(Índice!$G$102=1,"X","") | AY13: EQ-SAFE-441 | AZ13: Corrientes de fuga (contacto). AINUO
G14: EQ-SAFE-407 | H14: Cronómetro digital | K14: 0 | L14: 0 | O14: Otros: | P14: 0 | S14: 0 | T14: 0 | V14: =IF('Datos ensayos LUM.'!AR50=TRUE,"X","") | W14: EQ-SAFE-232 | X14: Boquillas de Tobera + Pulverizador + Bomba de presión | AE14: EQ-SAFE-409; EQ-SAFE-121 | AF14: Osciloscopio FLUKE | AI14: 0 | AJ14: 0 | AM14: EQ-SAFE-409; EQ-SAFE-121 | AN14: Osciloscopio | AP14: =IF('Datos ensayos LUM.'!AJ34=TRUE,"X","") | AQ14: EQ-SAFE-328 | AR14: Medidor temperatura 32 canales | AT14: =IF(Índice!$G$91=2,"X","") -> X | AU14: EQ-SAFE-318 | AV14: Comprobador termopares 2 canales | AX14: =IF(Índice!$G$102=2,"X","") -> X | AY14: EQ-SAFE-404 | AZ14: Corrientes de fuga lum. GW INSTEK GLC-1000
G15: Otros: | H15: 0 | O15: 0 | P15: 0 | W15: EQ-SAFE-211 | X15: Caudalímetro | AE15: EQ-SAFE-106 | AF15: Dedo de prueba articulado | AM15: EQ-SAFE-440 | AN15: Vatímetro GW-INSTEK | AP15: =IF('Datos ensayos LUM.'!AJ35=TRUE,"X","") | AQ15: EQ-SAFE-323 | AR15: Registrador 20+20 canales Graphtec | AU15: EQ-SAFE-104 | AV15: Presión con bola | AY15: EQ-SAFE-409; EQ-SAFE-121 | AZ15: Osciloscopio
O16: 0 | P16: 0 | W16: EQ-SAFE-106 | X16: Dedo de prueba articulado | AE16: EQ-SAFE-213 | AF16: Dinamómetro | AM16: EQ-SAFE-417 | AN16: Multímetro digital | AQ16: EQ-SAFE-324 | AR16: Registrador 20+20 canales Graphtec | AU16: EQ-SAFE-604 | AV16: Microscopio | AY16: EQ-SAFE-608 | AZ16: Resistencia para partes activas
K17: =Índice!D21 -> 4.12. Tornillos y conexiones mecánicas y prensaestopas | W17: EQ-SAFE-206 | X17: Pie de rey | AE17: EQ-SAFE-221 | AF17: Dinamómetro | AM17: EQ-SAFE-311; EQ-SAFE-312; EQ-SAFE-313 | AN17: Termohigrómetros | AQ17: EQ-SAFE-001 | AR17: Estabilizador de tensión | AU17: EQ-SAFE-121 | AV17: Regla graduada | AY17: EQ-SAFE-311; EQ-SAFE-312; EQ-SAFE-313 | AZ17: Termohigrómetros
G18: 4.6. Bloques de conexión | K18: {=IF(Índice!F21=TRUE,'BBDD Equipos 60598'!G53:H64,"NO ENSAYADO")} -> EQ-SAFE-213 | L18: Dinamómetro | W18: EQ-SAFE-107 EQ-SAFE-112 | X18: Varilla 50mm diámetro Esfera 50mm diámetro | AE18: EQ-SAFE-311; EQ-SAFE-312; EQ-SAFE-313 | AF18: Termohigrómetros | AM18: Otros: | AN18: 0 | AQ18: EQ-SAFE-011 | AR18: Medidor de resistencias de bobinado | AU18: EQ-SAFE-311; EQ-SAFE-312; EQ-SAFE-313 | AV18: Termohigrómetros | AY18: Otros: | AZ18: 0
G19: {=IF(Índice!F7=TRUE,'BBDD Equipos 60598'!G16:H21,"NO ENSAYADO")} -> EQ-SAFE-206 | H19: Pie de rey | K19: EQ-SAFE-216 | L19: Llave dinamométrica | O19: =Índice!D31 -> 4.24.2. Riesgo retiniano de luz azul | W19: EQ-SAFE-108 | X19: Varilla 2,5mm diámetro | AE19: Otros: | AF19: 0 | AM19: 0 | AN19: 0 | AQ19: Otros: | AR19: 0 | AU19: EQ-SAFE-407 | AV19: Cronómetro | AY19: 0 | AZ19: 0
G20: EQ-SAFE-207 | H20: Micrómetro digital | K20: EQ-SAFE-206 | L20: Pie de rey | O20: {=IF(Índice!F31=TRUE,'BBDD Equipos 60598'!G90:H94,"NO ENSAYADO")} -> EQ-SAFE-415 | P20: Espectrofotómetro | W20: EQ-SAFE-110 | X20: Esfera 12,5mm diámetro | AE20: 0 | AF20: 0 | AI20: =Índice!D61 -> 10.2.2. Rigidez dieléctrica | AQ20: 0 | AR20: 0 | AU20: Otros: | AV20: 0 | AY20: 0 | AZ20: 0
G21: EQ-SAFE-311; EQ-SAFE-312; EQ-SAFE-313 | H21: Termohigrómetros | K21: EQ-SAFE-207 | L21: Micrómetro digital | O21: EQ-SAFE-212 | P21: Flexómetro | W21: EQ-SAFE-109 | X21: Varilla 1 mm diámetro | AE21: 0 | AF21: 0 | AH21: =IF('Datos ensayos LUM.'!BF26=TRUE,"X","") | AI21: {=IF(Índice!F61=TRUE,'BBDD Equipos 60598'!AI13:AJ19,"NO ENSAYADO")} -> EQ-SAFE-402 | AJ21: Rigidez dieléctrica (GW INSTEK GPT 15002) | AQ21: 0 | AR21: 0 | AU21: 0 | AV21: 0
G22: Otros: | H22: 0 | K22: EQ-SAFE-311; EQ-SAFE-312; EQ-SAFE-313 | L22: Termohigrómetros | O22: Otros: | P22: 0 | W22: EQ-SAFE-309; EQ-SAFE-310 | X22: Termohigrómetros | AH22: =IF('Datos ensayos LUM.'!BF27=TRUE,"X","") | AI22: EQ-SAFE-403 | AJ22: Rigidez dieléctrica (GW INSTEK GPT 15004) | AU22: 0 | AV22: 0
G23: 0 | H23: 0 | K23: EQ-SAFE-214 | L23: Atornillador dinamométrico 60cNm | O23: 0 | P23: 0 | W23: EQ-SAFE-212 | X23: Flexómetro | AH23: =IF('Datos ensayos LUM.'!BF28=TRUE,"X","") | AI23: EQ-SAFE-403 | AJ23: Rigidez dieléctrica (GW INSTEK)
G24: 0 | H24: 0 | K24: EQ-SAFE-215 | L24: Atornillador dinamométrico 260cNm | O24: 0 | P24: 0 | W24: EQ-SAFE-330 | X24: Cámara climática | AI24: EQ-SAFE-311; EQ-SAFE-312; EQ-SAFE-313 | AJ24: Termohigrómetros | AU24: =Índice!D95 -> 13.3. Resistencia a la llama y a la inflamación
K25: EQ-SAFE-407 | L25: Cronómetro digital | V25: =IF('Datos ensayos LUM.'!BF26=TRUE,"X","") | W25: EQ-SAFE-403 | X25: Rigidez dieléctrica | AI25: Otros: | AJ25: 0 | AU25: {=IF(Índice!F95=TRUE,'BBDD Equipos 60598'!AM20:AN35,"NO ENSAYADO")} -> EQ-SAFE-307 | AV25: Llama de aguja
G26: =Índice!D8 -> 4.7.2. Bornes y conexiones a la red de alimentación | K26: EQ-SAFE-212 | L26: Flexómetro | V26: =IF('Datos ensayos LUM.'!BF27=TRUE,"X","") | W26: EQ-SAFE-402 | X26: Rigidez dieléctrica | AI26: 0 | AJ26: 0 | AU26: EQ-SAFE-308 | AV26: Mechero Bunsen
G27: {=IF(Índice!F8=TRUE,'BBDD Equipos 60598'!G23:H28,"NO ENSAYADO")} -> EQ-SAFE-206 | H27: Pie de rey | K27: Otros: | L27: 0 | O27: =Índice!D32 -> 4.28. Fijación de los dispositivos de control sensibles a la temperatura | V27: =IF('Datos ensayos LUM.'!BF28=TRUE,"X","") | W27: EQ-SAFE-403 | X27: Rigidez dieléctrica (GW INSTEK) | AI27: 0 | AJ27: 0 | AU27: EQ-SAFE-407 | AV27: Cronómetro
G28: EQ-SAFE-207 | H28: Micrómetro digital | K28: 0 | L28: 0 | O28: {=IF(Índice!F31=TRUE,'BBDD Equipos 60598'!G96:H100,"NO ENSAYADO")} -> EQ-SAFE-330 | P28: Cámara climática | V28: =IF('Datos ensayos LUM.'!BE26=TRUE,"X","") | W28: EQ-SAFE-403 | X28: Medidor resistencia de aislamiento | AU28: EQ-SAFE-311; EQ-SAFE-312; EQ-SAFE-313 | AV28: Termohigrómetros
G29: EQ-SAFE-311; EQ-SAFE-312; EQ-SAFE-313 | H29: Termohigrómetros | K29: 0 | L29: 0 | O29: EQ-SAFE-212 | P29: Flexómetro | V29: =IF('Datos ensayos LUM.'!BE28=TRUE,"X","") | W29: EQ-SAFE-403 | X29: Medidor resistencia de aislamiento | AU29: RC-SAFE-013 | AV29: Gas propano
G30: Otros: | H30: 0 | O30: Otros: | P30: 0 | W30: EQ-SAFE-407 | X30: Cronómetro digital | AU30: Otros: | AV30: 0
G31: 0 | H31: 0 | O31: 0 | P31: 0 | V31: =IF('Datos ensayos LUM.'!AV70=TRUE,"X","") | W31: EQ-SAFE-326 | X31: Cámara de polvo | AI31: =Índice!D66 -> 10.3. Corrientes de fuga | AU31: 0 | AV31: 0
G32: 0 | H32: 0 | O32: 0 | P32: 0 | W32: Otros: | X32: 0 | AH32: =IF('Datos ensayos LUM.'!BG24=TRUE,"X","") | AI32: {=IF(Índice!F66=TRUE,'BBDD Equipos 60598'!AI21:AJ26,"NO ENSAYADO")} -> EQ-SAFE-441 | AJ32: Corrientes de fuga AINUO | AU32: 0 | AV32: 0
K33: =Índice!D22 -> 4.13. Ensayo de golpe martillo impacto | W33: 0 | X33: 0 | AH33: =IF('Datos ensayos LUM.'!BG25=TRUE,"X","") | AI33: EQ-SAFE-404 | AJ33: Corrientes de fuga GW INSTEK - GLC-1000 | AU33: 15.3.2 Hilo inandescente | AV33: 0
G34: =Índice!D9 -> 4.9. Revestimientos y manguitos aislantes | K34: {=IF(Índice!F22=TRUE,'BBDD Equipos 60598'!G66:H71,"NO ENSAYADO")} -> EQ-SAFE-122 | L34: Dedo rígido de prueba rígido | W34: 0 | X34: 0 | AI34: EQ-SAFE-311; EQ-SAFE-312; EQ-SAFE-313 | AJ34: Termohigrómetros | AU34: EQ-SAFE-306 | AV34: Equipo de hilo incandescente
F35: =IF('Datos ensayos LUM.'!D108=TRUE,"X","") -> X | G35: {=IF(Índice!F9=TRUE,'BBDD Equipos 60598'!G30:H43,"NO ENSAYADO")} -> EQ-SAFE-305 | H35: Estufa / horno | K35: EQ-SAFE-101 | L35: Martillo resorte | W35: 0 | X35: 0 | AI35: Otros: | AJ35: 0 | AU35: EQ-SAFE-407 | AV35: Cronómetro
F36: =IF('Datos ensayos LUM.'!D109=TRUE,"X","") | G36: EQ-SAFE-304 | H36: Estufa / Horno AUTOSTRONG | K36: EQ-SAFE-601 | L36: Indicador de contacto eléctrico | W36: 0 | X36: 0 | AI36: 0 | AJ36: 0 | AU36: EQ-SAFE-311; EQ-SAFE-312; EQ-SAFE-313 | AV36: Termohigrómetros
G37: EQ-SAFE-301 | H37: Recinto de temperaturas | K37: EQ-SAFE-311; EQ-SAFE-312; EQ-SAFE-313 | L37: Termohigrómetros | W37: 0 | X37: 0 | AI37: 0 | AJ37: 0 | AU37: Otros: | AV37: 0
G38: EQ-SAFE-330 | H38: Cámara climática | K38: Otros: | L38: 0 | W38: 0 | X38: 0 | AU38: 0 | AV38: 0
G39: EQ-SAFE-206 | H39: Pie de rey | K39: 0 | L39: 0 | W39: 0 | X39: 0 | AU39: 0 | AV39: 0
F40: =IF('Datos ensayos LUM.'!BF26=TRUE,"X","") | G40: EQ-SAFE-403 | H40: Rigidez dieléctrica | W40: 0 | X40: 0 | AU40: 0 | AV40: 0
F41: =IF('Datos ensayos LUM.'!BF27=TRUE,"X","") | G41: EQ-SAFE-402 | H41: Rigidez dieléctrica + Resist aisl + Tierra | AU41: {='BBDD Equipos 60598'!AM36:AN47} -> 15.4 Frormación de caminos conductores | AV41: 0
